<mujoco model="base">
  <statistic extent="2" meansize=".05" />
  <compiler angle="radian" coordinate="local" eulerseq="XYZ" />
  <option impratio="1" timestep="0.002" solver="Newton" iterations="30" tolerance="1e-10" jacobian="sparse" cone="elliptic" integrator="implicit" />
  <size nconmax="5000" njmax="5000" />

  

  <extension />

  <asset>
    <texture type="skybox" builtin="gradient" rgb1="1. 1. 0.9" rgb2="0.9 0.9 0.81" width="512" height="512" />
    <texture name="texplane" type="2d" builtin="checker" rgb1=".2 .3 .4" rgb2=".1 0.15 0.2" width="512" height="512" mark="cross" markrgb=".8 .8 .8" />
    <material name="matplane" reflectance="0.3" texture="texplane" texrepeat="1 1" texuniform="true" />
  <mesh name="BASE_mesh" file="/home/qj/git/utilsrepo/sample_mujoco/sample_mujoco/assets/densovs060/meshes/BASE_mesh.stl" />
        <mesh name="J1_mesh" file="/home/qj/git/utilsrepo/sample_mujoco/sample_mujoco/assets/densovs060/meshes/J1_mesh.stl" />
        <mesh name="J2_mesh" file="/home/qj/git/utilsrepo/sample_mujoco/sample_mujoco/assets/densovs060/meshes/J2_mesh.stl" />
        <mesh name="J3_mesh" file="/home/qj/git/utilsrepo/sample_mujoco/sample_mujoco/assets/densovs060/meshes/J3_mesh.stl" />
        <mesh name="J4_mesh" file="/home/qj/git/utilsrepo/sample_mujoco/sample_mujoco/assets/densovs060/meshes/J4_mesh.stl" />
        <mesh name="J5_mesh" file="/home/qj/git/utilsrepo/sample_mujoco/sample_mujoco/assets/densovs060/meshes/J5_mesh.stl" />
        <mesh name="Flange_mesh" file="/home/qj/git/utilsrepo/sample_mujoco/sample_mujoco/assets/densovs060/meshes/Flange_mesh.stl" />
    </asset>

  <visual>
    <rgba haze="0.15 0.25 0.35 1" />
    <quality shadowsize="2048" />
    <map znear="0.001" stiffness="700" shadowscale="0.5" fogstart="10" fogend="15" zfar="40" haze="0.3" />
  </visual>

  <actuator><position name="j1_act" kp="10000.0" kv="200" inheritrange="0.99" joint="j1" />
        <position name="j2_act" kp="100.0" kv="10" inheritrange="0.99" joint="j2" />
        <position name="j3_act" kp="1500.0" kv="100" inheritrange="0.99" joint="j3" />
        <position name="j4_act" kp="100.0" kv="20" inheritrange="0.99" joint="j4" />
        <position name="j5_act" kp="100.0" kv="10" inheritrange="0.99" joint="j5" />
        <position name="flange_act" kp="100.0" kv="0" inheritrange="0.99" joint="flange" />
        <motor ctrllimited="true" ctrlrange="-80.0 80.0" joint="j1" name="torq_j1" />
        <motor ctrllimited="true" ctrlrange="-80.0 80.0" joint="j2" name="torq_j2" />
        <motor ctrllimited="true" ctrlrange="-80.0 80.0" joint="j3" name="torq_j3" />
        <motor ctrllimited="true" ctrlrange="-80.0 80.0" joint="j4" name="torq_j4" />
        <motor ctrllimited="true" ctrlrange="-80.0 80.0" joint="j5" name="torq_j5" />
        <motor ctrllimited="true" ctrlrange="-12.0 12.0" joint="flange" name="torq_flange" />
    </actuator>

  <worldbody>
    
    <camera mode="fixed" pos="0 -1 1.5" quat="0.866 0.5 0 0" />
    <camera mode="fixed" pos="1. -1.2 0.8" quat="0.687 0.527 0.304 0.397" />
    <camera mode="fixed" pos="-1.8 -1.1 .7" quat="0.73296292  0.56242221 -0.23296292 -0.30360319" />
    <camera mode="fixed" pos="-1 -1.5 .5" quat="0.707 0.707 0 0" />
    <camera mode="fixed" pos="9.7 -1.0 1.1" quat="0.687 0.527 0.304 0.397" />
    <camera mode="fixed" pos="4.5 -8.0 .5" quat="0.707 0.707 0 0" />
    <geom condim="1" material="matplane" name="floor" pos="0 0 0" size="3 3 .125" type="plane" />
    <light directional="true" diffuse=".4 .4 .4" specular="0.1 0.1 0.1" pos="0 0 5.0" dir="0 0 -1" castshadow="false" />
    <light directional="true" diffuse=".6 .6 .6" specular="0.2 0.2 0.2" pos="0 0 4" dir="0 0 -1" />
    
    <site name="ax_y" pos="0 0.1 0" quat="0.707 0.707 0 0" size="0.01 0.1" rgba="1 1 0 0.3" type="cylinder" group="1" />
    <site name="ax_x" pos="0.1 0 0" quat="0.707 0 0.707 0" size="0.01 0.1" rgba="0 0 1 0.3" type="cylinder" group="1" />

    

    
    
    
  <geom type="mesh" mesh="BASE_mesh" />
        <body name="J1" pos="0 0 0.182">
            <inertial pos="0.013885 -0.005997 0.043991" quat="0.707107 0 0 0.707107" mass="4.327" diaginertia="0.032502 0.025492 0.01779" />
            <joint name="j1" pos="0 0 0" axis="0 0 1" limited="true" range="-2.96706 2.96706" ref="0" />
            <geom pos="0 0 0.182" type="mesh" mesh="J1_mesh" />
            <body name="J2" pos="0 0 0.163">
                <inertial pos="0.015837 -0.073696 0.010087" quat="0.5 0.5 -0.5 0.5" mass="9.475" diaginertia="0.112871 0.108024 0.025579" />
                <joint name="j2" pos="0 0 0" axis="0 1 0" limited="true" range="-2.0944 2.0944" ref="0" />
                <geom pos="0 0 0.163" type="mesh" mesh="J2_mesh" />
                <body name="J3" pos="0 0 0.305">
                    <inertial pos="0.011544 -0.057408 0.006203" quat="0.5 0.5 -0.5 0.5" mass="4.097" diaginertia="0.016882 0.015999 0.00638" />
                    <joint name="j3" pos="0 0 0" axis="0 1 0" limited="true" range="-2.18166 2.70526" ref="0" />
                    <geom pos="0 0 0.305" type="mesh" mesh="J3_mesh" />
                    <body name="J4" pos="-0.01 0 0.165">
                        <inertial pos="0.003998 -0.004975 0.052919" quat="0.707107 0 0 0.707107" mass="1.779" diaginertia="0.005266 0.005106 0.002621" />
                        <joint name="j4" pos="0 0 0" axis="0 0 1" limited="true" range="-4.71239 4.71239" ref="0" />
                        <geom pos="-0.01 0 0.165" type="mesh" mesh="J4_mesh" />
                        <body name="J5" pos="0 0 0.135">
                            <inertial pos="0.011902 -0.004739 0.010398" quat="0.5 0.5 0.5 0.5" mass="1.211" diaginertia="0.001629 0.001615 0.001093" />
                            <joint name="j5" pos="0 0 0" axis="0 1 0" limited="true" range="-2.0944 2.0944" ref="0" />
                            <geom pos="0 0 0.135" type="mesh" mesh="J5_mesh" />
                            <body name="Flange" pos="0 0 0.07">
                                <inertial pos="-0.000401015 0.0770342 0.0962886" quat="0.486311 0.507364 0.4441 0.555751" mass="4.154" diaginertia="0.0349016 0.0227238 0.0216365" />
                                <joint name="flange" pos="0 0 0" axis="0 0 1" limited="true" range="-6.28319 6.28319" ref="0" />
                                <geom pos="0 0 0.07" type="mesh" mesh="Flange_mesh" />
                                <body name="eef_body" pos="0 0 0.02">
                                    <site name="eef_site" pos="0 0 0." size="0.01 0.01 0.01" rgba="1 0 0 0.3" type="sphere" group="1" />
                                </body>
                            </body>
                        </body>
                    </body>
                </body>
            </body>
        </body>
    </worldbody>

  <sensor />

  <equality />

  <contact />
  
  
</mujoco>